Workbook

Sheet Instruções
B2: Metodologia de Priorização v2 — Matriz de Impacto × Esforço
B3: Sistema FIEA • Setor de Tecnologias Digitais • Anexo A v2
B6: O que mudou em relação à versão anterior
B7: • Aderência Estratégica passa de 25% para 35% e amarra cada demanda a um dos 19 objetivos do Mapa Estratégico Regional 2026-2028.
B8: • Risco Regulatório reduzido de 20% para 15% — evita dupla contagem com o pilar F2 (Governança e Compliance).
B9: • Novo critério Alcance (10%) — captura quantas pessoas, áreas ou unidades são impactadas pela entrega.
B10: • Cliente, Financeiro e Eficiência redistribuídos para acomodar o novo peso da Estratégia.
B11: • Modulador de criticidade estratégica (× 0,8 / × 1,0 / × 1,3) — aplicado pelo PMO conforme decisão anual de focos do ciclo.
B12: • Confiança da estimativa (Alta / Média / Baixa) — divide o impacto por 1,5 quando a baixa, penalizando chute sem dados.
B13: • Visualização da matriz ganha overlay: cor do ponto = perspectiva do Mapa, tamanho = profundidade do impacto estratégico.
B15: Como usar esta planilha
B16: • Aba Configuração — define modulador de cada pilar do Mapa. Hoje todos em 1.0 (PMO ativa quando definir focos do ciclo).
... B34: Quadrante = lookup(Impacto, Esforço) na matriz 2×2 com corte em 3.0.

Sheet Configuração
B2: Configuração da Metodologia
B4: Pesos dos critérios
B6: Eixo Impacto
B7: Aderência Estratégica | C7: 0.35
B8: Cliente | C8: 0.15
B9: Financeiro | C9: 0.15
B10: Eficiência Operacional | C10: 0.1
B11: Risco Regulatório | C11: 0.15
B12: Alcance | C12: 0.1
B13: Total Impacto | C13: =SUM(C7:C12) -> 1
B15: Eixo Esforço
B16: Documentação existente | C16: 0.15
B17: Áreas envolvidas | C17: 0.15
B18: Maturidade do escopo | C18: 0.2
B19: Complexidade técnica | C19: 0.25
B20: Integrações e dependências | C20: 0.25
B21: Total Esforço | C21: =SUM(C16:C20) -> 1
B23: Fator de Confiança da Estimativa
B24: Nível | C24: Divisor | D24: Descrição
B25: Alta | C25: 1 | D25: Estimativa baseada em dados sólidos
B26: Média | C26: 1 | D26: Estimativa razoável, parte por inferência
B27: Baixa | C27: 1.5 | D27: Estimativa sem dados — divide o impacto
B29: Modulador de Criticidade Estratégica por Pilar
B30: Defina anualmente com a diretoria. × 1.3 para pilares de foco do ciclo, × 0.8 para sustentação, × 1.0 padrão. Hoje todos em 1.0.
B31: Código | C31: Objetivo Estratégico | D31: Modulador
B32: F1 | C32: Sustentabilidade financeira e institucional | D32: 1
B33: F2 | C33: Governança Corporativa e Compliance | D33: 1
B34: F3 | C34: Impacto ambiental e social positivo | D34: 1
B35: M1 | C35: Fortalecer a marca em atributos e propósito | D35: 1
B36: I1 | C36: Negócios sustentáveis e inovadores | D36: 1
B37: I2 | C37: Soluções e produtos inovadores | D37: 1
B38: I3 | C38: Cultura da inovação como motor | D38: 1
B39: C1 | C39: Ampliar cobertura da indústria | D39: 1
B40: C2 | C40: Conquistar, reter e expandir clientes | D40: 1
B41: C3 | C41: Dominar pontos de contato com cliente | D41: 1
B42: O1 | C42: Saúde e Segurança como solução | D42: 1
B43: O2 | C43: Qualidade pedagógica Sesi | D43: 1
... B50: H2 | C50: Lideranças com visão estratégica | D50: 1

Sheet Critérios
B2: Critérios de Pontuação — Escalas 1 a 5
B4: EIXO IMPACTO
B5: Critério | C5: Peso | D5: 1 (mínimo) | E5: 3 (médio) | F5: 5 (máximo)
B6: Aderência Estratégica | C6: 35% | D6: Sem aderência a nenhum dos 19 objetivos do Mapa | E6: Contribui com profundidade média para um pilar | F6: Sustentação central de um pilar do Mapa
B7: Cliente | C7: 15% | D7: Não impacta experiência do cliente | E7: Impacto moderado em satisfação | F7: Transforma experiência do cliente final
B8: Financeiro | C8: 15% | D8: Sem impacto financeiro relevante | E8: Economia ou receita moderada | F8: Grande potencial de transformação econômica
B9: Eficiência Operacional | C9: 10% | D9: Não traz ganho de eficiência | E9: Ganho moderado de eficiência | F9: Efeito significativo em indicadores e chamados
B10: Risco Regulatório | C10: 15% | D10: Sem implicação regulatória | E10: Implicação moderada, sem prazo crítico | F10: Crítico em LGPD, ANPD, TCU ou Sistema S
B11: Alcance | C11: 10% | D11: Afeta < 50 pessoas ou 1 unidade | E11: Afeta 500-5.000 pessoas ou múltiplas unidades | F11: Afeta > 10.000 pessoas ou todo o Sistema FIEA
B13: EIXO ESFORÇO
B14: Critério | C14: Peso | D14: 1 (mínimo) | E14: 3 (médio) | F14: 5 (máximo)
B15: Documentação | C15: 15% | D15: Documento qualificado do estado atual | E15: Documento existe mas não qualificado | F15: Não possui documentação
B16: Áreas envolvidas | C16: 15% | D16: Até 2 áreas | E16: 3 a 4 áreas | F16: 5 ou mais áreas
B17: Maturidade do escopo | C17: 20% | D17: Escopo claro, requisitos definidos | E17: Escopo parcial, alguns refinamentos | F17: Escopo em construção, muitos requisitos a definir
B18: Complexidade técnica | C18: 25% | D18: Solução simples, padrões conhecidos | E18: Média complexidade, alguns padrões novos | F18: Alta complexidade, arquitetura ou tecnologia novas
B19: Integrações | C19: 25% | D19: Solução isolada, sem integrações | E19: Integra com 1-2 sistemas internos | F19: Múltiplas integrações com legados e terceiros

Sheet Portfólio Pontuado
A1: Portfólio Pontuado — Metodologia v2
A2: Colunas com fundo claro foram pré-classificadas por heurística e devem ser revisadas pelo PMO. Confiança começa em Baixa — eleve para Média/Alta após validação.
A4: Projeto | B4: PO | C4: Diretoria | D4: Pilar | E4: Aderência | F4: Cliente | G4: Financ. | H4: Efic. | I4: Risco | J4: Alcance | K4: Doc. | L4: Áreas | M4: Matur. | N4: Complex. | O4: Integr. | P4: Confiança | Q4: Impacto bruto | R4: Modulador | S4: Div. Conf. | T4: IMPACTO | U4: ESFORÇO | V4: QUADRANTE
A5: Matrícula no AVA | Automação | B5: Claudio Vieira | C5: Diretoria de Educação | D5: O3 | E5: 5 | F5: 5 | G5: 2 | H5: 4 | I5: 1 | J5: 5 | K5: 3 | L5: 2 | M5: 2 | N5: 4 | O5: 4 | P5: Média | Q5: =E5*0.35+F5*0.15+G5*0.15+H5*0.1+I5*0.15+J5*0.1 -> 3.85 | R5: =VLOOKUP(D5,Configuração!$B$32:$D$50,3,FALSE()) -> 1 | S5: =IF(P5="Baixa",1.5,1) -> 1 | T5: =Q5*R5/S5 -> 3.85 | U5: =K5*0.15+L5*0.15+M5*0.2+N5*0.25+O5*0.25 -> 3.15 | V5: =IF(AND(T5>=3,U5<3),"Quick Win",IF(AND(T5>=3,U5>=3),"Big Bet",IF(AND(T5<3,U5<3),"Fill In","Money Pit"))) -> Big Bet
A6: Automação Ponto Extra | B6: Claudio Vieira | C6: Diretoria de Educação | D6: H1 | E6: 3 | F6: 2 | G6: 2 | H6: 4 | I6: 1 | J6: 2 | K6: 3 | L6: 2 | M6: 2 | N6: 4 | O6: 2 | P6: Média | Q6: =E6*0.35+F6*0.15+G6*0.15+H6*0.1+I6*0.15+J6*0.1 -> 2.4 | R6: =VLOOKUP(D6,Configuração!$B$32:$D$50,3,FALSE()) -> 1 | S6: =IF(P6="Baixa",1.5,1) -> 1 | T6: =Q6*R6/S6 -> 2.4 | U6: =K6*0.15+L6*0.15+M6*0.2+N6*0.25+O6*0.25 -> 2.65 | V6: =IF(AND(T6>=3,U6<3),"Quick Win",IF(AND(T6>=3,U6>=3),"Big Bet",IF(AND(T6<3,U6<3),"Fill In","Money Pit"))) -> Fill In
A7: Cadastro | Email do RH | B7: Claudio Vieira | C7: Diretoria de Educação | D7: O6 | E7: 3 | F7: 2 | G7: 2 | H7: 3 | I7: 1 | J7: 2 | K7: 3 | L7: 2 | M7: 2 | N7: 3 | O7: 2 | P7: Média | Q7: =E7*0.35+F7*0.15+G7*0.15+H7*0.1+I7*0.15+J7*0.1 -> 2.3 | R7: =VLOOKUP(D7,Configuração!$B$32:$D$50,3,FALSE()) -> 1 | S7: =IF(P7="Baixa",1.5,1) -> 1 | T7: =Q7*R7/S7 -> 2.3 | U7: =K7*0.15+L7*0.15+M7*0.2+N7*0.25+O7*0.25 -> 2.4 | V7: =IF(AND(T7>=3,U7<3),"Quick Win",IF(AND(T7>=3,U7>=3),"Big Bet",IF(AND(T7<3,U7<3),"Fill In","Money Pit"))) -> Fill In
A8: Contrato - Valor Total | B8: Claudio Vieira | C8: Diretoria de Educação | D8: O6 | E8: 3 | F8: 2 | G8: 2 | H8: 3 | I8: 1 | J8: 2 | K8: 3 | L8: 2 | M8: 2 | N8: 3 | O8: 2 | P8: Média | Q8: =E8*0.35+F8*0.15+G8*0.15+H8*0.1+I8*0.15+J8*0.1 -> 2.3 | R8: =VLOOKUP(D8,Configuração!$B$32:$D$50,3,FALSE()) -> 1 | S8: =IF(P8="Baixa",1.5,1) -> 1 | T8: =Q8*R8/S8 -> 2.3 | U8: =K8*0.15+L8*0.15+M8*0.2+N8*0.25+O8*0.25 -> 2.4 | V8: =IF(AND(T8>=3,U8<3),"Quick Win",IF(AND(T8>=3,U8>=3),"Big Bet",IF(AND(T8<3,U8<3),"Fill In","Money Pit"))) -> Fill In
A9: Senai Conecta | Melhoria | B9: Claudio Vieira | C9: Diretoria de Educação | D9: O3 | E9: 5 | F9: 2 | G9: 2 | H9: 3 | I9: 1 | J9: 2 | K9: 3 | L9: 2 | M9: 2 | N9: 3 | O9: 2 | P9: Média | Q9: =E9*0.35+F9*0.15+G9*0.15+H9*0.1+I9*0.15+J9*0.1 -> 3 | R9: =VLOOKUP(D9,Configuração!$B$32:$D$50,3,FALSE()) -> 1 | S9: =IF(P9="Baixa",1.5,1) -> 1 | T9: =Q9*R9/S9 -> 3 | U9: =K9*0.15+L9*0.15+M9*0.2+N9*0.25+O9*0.25 -> 2.4 | V9: =IF(AND(T9>=3,U9<3),"Quick Win",IF(AND(T9>=3,U9>=3),"Big Bet",IF(AND(T9<3,U9<3),"Fill In","Money Pit"))) -> Quick Win
A10: Gestão de telefonia móvel | B10: Ewerton Costa do Nascimento | C10: Diretoria de Serviços Compartilhados | D10: H1 | E10: 3 | F10: 2 | G10: 2 | H10: 3 | I10: 1 | J10: 2 | K10: 3 | L10: 2 | M10: 2 | N10: 3 | O10: 2 | P10: Média | Q10: =E10*0.35+F10*0.15+G10*0.15+H10*0.1+I10*0.15+J10*0.1 -> 2.3 | R10: =VLOOKUP(D10,Configuração!$B$32:$D$50,3,FALSE()) -> 1 | S10: =IF(P10="Baixa",1.5,1) -> 1 | T10: =Q10*R10/S10 -> 2.3 | U10: =K10*0.15+L10*0.15+M10*0.2+N10*0.25+O10*0.25 -> 2.4 | V10: =IF(AND(T10>=3,U10<3),"Quick Win",IF(AND(T10>=3,U10>=3),"Big Bet",IF(AND(T10<3,U10<3),"Fill In","Money Pit"))) -> Fill In
A11: Corrida Sesi | B11: Francisco Oliveira - Mesha 71 | C11: Diretoria de Segurança e Saúde | D11: O1 | E11: 5 | F11: 2 | G11: 2 | H11: 3 | I11: 1 | J11: 5 | K11: 3 | L11: 2 | M11: 2 | N11: 3 | O11: 2 | P11: Média | Q11: =E11*0.35+F11*0.15+G11*0.15+H11*0.1+I11*0.15+J11*0.1 -> 3.3 | R11: =VLOOKUP(D11,Configuração!$B$32:$D$50,3,FALSE()) -> 1 | S11: =IF(P11="Baixa",1.5,1) -> 1 | T11: =Q11*R11/S11 -> 3.3 | U11: =K11*0.15+L11*0.15+M11*0.2+N11*0.25+O11*0.25 -> 2.4 | V11: =IF(AND(T11>=3,U11<3),"Quick Win",IF(AND(T11>=3,U11>=3),"Big Bet",IF(AND(T11<3,U11<3),"Fill In","Money Pit"))) -> Quick Win
A12: Gestão de atividades | B12: Francisco Oliveira - Mesha 71 | C12: nan | D12: O5 | E12: 4 | F12: 2 | G12: 2 | H12: 3 | I12: 1 | J12: 2 | K12: 3 | L12: 2 | M12: 2 | N12: 3 | O12: 2 | P12: Média | Q12: =E12*0.35+F12*0.15+G12*0.15+H12*0.1+I12*0.15+J12*0.1 -> 2.65 | R12: =VLOOKUP(D12,Configuração!$B$32:$D$50,3,FALSE()) -> 1 | S12: =IF(P12="Baixa",1.5,1) -> 1 | T12: =Q12*R12/S12 -> 2.65 | U12: =K12*0.15+L12*0.15+M12*0.2+N12*0.25+O12*0.25 -> 2.4 | V12: =IF(AND(T12>=3,U12<3),"Quick Win",IF(AND(T12>=3,U12>=3),"Big Bet",IF(AND(T12<3,U12<3),"Fill In","Money Pit"))) -> Fill In
A13: Mensageria - FRPRT | B13: Francisco Oliveira - Mesha 71 | C13: nan | D13: O1 | E13: 5 | F13: 4 | G13: 2 | H13: 4 | I13: 1 | J13: 5 | K13: 3 | L13: 2 | M13: 2 | N13: 3 | O13: 4 | P13: Média | Q13: =E13*0.35+F13*0.15+G13*0.15+H13*0.1+I13*0.15+J13*0.1 -> 3.7 | R13: =VLOOKUP(D13,Configuração!$B$32:$D$50,3,FALSE()) -> 1 | S13: =IF(P13="Baixa",1.5,1) -> 1 | T13: =Q13*R13/S13 -> 3.7 | U13: =K13*0.15+L13*0.15+M13*0.2+N13*0.25+O13*0.25 -> 2.9 | V13: =IF(AND(T13>=3,U13<3),"Quick Win",IF(AND(T13>=3,U13>=3),"Big Bet",IF(AND(T13<3,U13<3),"Fill In","Money Pit"))) -> Quick Win
A14: IsMarkting - Solicitações de serviços de marketing | B14: Francisco Oliveira - Mesha 71 | C14: Diretoria Comercial e Marketing | D14: C2 | E14: 4 | F14: 4 | G14: 2 | H14: 3 | I14: 1 | J14: 2 | K14: 3 | L14: 2 | M14: 2 | N14: 3 | O14: 2 | P14: Média | Q14: =E14*0.35+F14*0.15+G14*0.15+H14*0.1+I14*0.15+J14*0.1 -> 2.95 | R14: =VLOOKUP(D14,Configuração!$B$32:$D$50,3,FALSE()) -> 1 | S14: =IF(P14="Baixa",1.5,1) -> 1 | T14: =Q14*R14/S14 -> 2.95 | U14: =K14*0.15+L14*0.15+M14*0.2+N14*0.25+O14*0.25 -> 2.4 | V14: =IF(AND(T14>=3,U14<3),"Quick Win",IF(AND(T14>=3,U14>=3),"Big Bet",IF(AND(T14<3,U14<3),"Fill In","Money Pit"))) -> Fill In
A15: Avaliação FRPRT - METODOLOGIA DN | B15: Francisco Oliveira - Mesha 71 | C15: Diretoria de Segurança e Saúde | D15: O1 | E15: 5 | F15: 2 | G15: 2 | H15: 3 | I15: 3 | J15: 5 | K15: 3 | L15: 2 | M15: 2 | N15: 3 | O15: 4 | P15: Média | Q15: =E15*0.35+F15*0.15+G15*0.15+H15*0.1+I15*0.15+J15*0.1 -> 3.6 | R15: =VLOOKUP(D15,Configuração!$B$32:$D$50,3,FALSE()) -> 1 | S15: =IF(P15="Baixa",1.5,1) -> 1 | T15: =Q15*R15/S15 -> 3.6 | U15: =K15*0.15+L15*0.15+M15*0.2+N15*0.25+O15*0.25 -> 2.9 | V15: =IF(AND(T15>=3,U15<3),"Quick Win",IF(AND(T15>=3,U15>=3),"Big Bet",IF(AND(T15<3,U15<3),"Fill In","Money Pit"))) -> Quick Win
A16: Sistema de Gerenciamento de Treinamentos | B16: Francisco Oliveira - Mesha 71 | C16: Diretoria de Serviços Compartilhados | D16: O6 | E16: 3 | F16: 5 | G16: 2 | H16: 3 | I16: 1 | J16: 5 | K16: 3 | L16: 2 | M16: 2 | N16: 3 | O16: 2 | P16: Média | Q16: =E16*0.35+F16*0.15+G16*0.15+H16*0.1+I16*0.15+J16*0.1 -> 3.05 | R16: =VLOOKUP(D16,Configuração!$B$32:$D$50,3,FALSE()) -> 1 | S16: =IF(P16="Baixa",1.5,1) -> 1 | T16: =Q16*R16/S16 -> 3.05 | U16: =K16*0.15+L16*0.15+M16*0.2+N16*0.25+O16*0.25 -> 2.4 | V16: =IF(AND(T16>=3,U16<3),"Quick Win",IF(AND(T16>=3,U16>=3),"Big Bet",IF(AND(T16<3,U16<3),"Fill In","Money Pit"))) -> Quick Win
... A81: Sistema para Prestação de Contas de Projetos | B81: Ronaldo de Melo - Mesha | C81: nan | D81: O6 | E81: 3 | F81: 2 | G81: 2 | H81: 3 | I81: 1 | J81: 2 | K81: 3 | L81: 2 | M81: 2 | N81: 3 | O81: 2 | P81: Média | Q81: =E81*0.35+F81*0.15+G81*0.15+H81*0.1+I81*0.15+J81*0.1 -> 2.3 | R81: =VLOOKUP(D81,Configuração!$B$32:$D$50,3,FALSE()) -> 1 | S81: =IF(P81="Baixa",1.5,1) -> 1 | T81: =Q81*R81/S81 -> 2.3 | U81: =K81*0.15+L81*0.15+M81*0.2+N81*0.25+O81*0.25 -> 2.4 | V81: =IF(AND(T81>=3,U81<3),"Quick Win",IF(AND(T81>=3,U81>=3),"Big Bet",IF(AND(T81<3,U81<3),"Fill In","Money Pit"))) -> Fill In

Sheet Pilares Estratégicos
B2: Mapa Estratégico Regional 2026-2028 — 19 objetivos
B3: Propósito: Transformar a vida das pessoas e das indústrias como ponte para o futuro
B5: Código | C5: Perspectiva | D5: Objetivo Estratégico
B6: F1 | C6: Financeiro & Administrativo | D6: Sustentabilidade financeira e institucional
B7: F2 | C7: Financeiro & Administrativo | D7: Governança Corporativa e Compliance
B8: F3 | C8: Financeiro & Administrativo | D8: Impacto ambiental e social positivo
B9: M1 | C9: Marca | D9: Fortalecer a marca em atributos e propósito
B10: I1 | C10: Inovação | D10: Negócios sustentáveis e inovadores
B11: I2 | C11: Inovação | D11: Soluções e produtos inovadores
B12: I3 | C12: Inovação | D12: Cultura da inovação como motor
B13: C1 | C13: Cliente | D13: Ampliar cobertura da indústria
B14: C2 | C14: Cliente | D14: Conquistar, reter e expandir clientes
B15: C3 | C15: Cliente | D15: Dominar pontos de contato com cliente
B16: O1 | C16: Capital Organizacional | D16: Saúde e Segurança como solução
... B24: H2 | C24: Capital Humano | D24: Lideranças com visão estratégica

Sheet Matriz
B2: Matriz Impacto × Esforço — 77 projetos
B3: Cada ponto é um projeto. Eixo X = Esforço (1-5), Eixo Y = Impacto Efetivo (1-5). Linhas em 3.0 dividem os quadrantes.
B5: Legenda das cores | P5: Dados auxiliares para gráfico (ocultos do usuário)
B6: F | C6: Financeiro & Administrativo | P6: Esforço | Q6: Impacto | R6: Perspectiva
B7: M | C7: Marca | P7: ='Portfólio Pontuado'!U20 -> 2.4 | Q7: ='Portfólio Pontuado'!T20 -> 2.65 | R7: F
B8: I | C8: Inovação | P8: ='Portfólio Pontuado'!U22 -> 2.4 | Q8: ='Portfólio Pontuado'!T22 -> 2.65 | R8: F
B9: C | C9: Cliente | P9: ='Portfólio Pontuado'!U27 -> 2.9 | Q9: ='Portfólio Pontuado'!T27 -> 3.55 | R9: F
B10: O | C10: Capital Organizacional | P10: ='Portfólio Pontuado'!U28 -> 2.9 | Q10: ='Portfólio Pontuado'!T28 -> 2.95 | R10: F
B11: H | C11: Capital Humano | P11: ='Portfólio Pontuado'!U49 -> 2.9 | Q11: ='Portfólio Pontuado'!T49 -> 3.25 | R11: F
P12: ='Portfólio Pontuado'!U51 -> 2.4 | Q12: ='Portfólio Pontuado'!T51 -> 3.1 | R12: F
P13: ='Portfólio Pontuado'!U55 -> 3.15 | Q13: ='Portfólio Pontuado'!T55 -> 3.85 | R13: F
P14: ='Portfólio Pontuado'!U56 -> 3.15 | Q14: ='Portfólio Pontuado'!T56 -> 4 | R14: F
P15: ='Portfólio Pontuado'!U59 -> 3.95 | Q15: ='Portfólio Pontuado'!T59 -> 4 | R15: F
P16: ='Portfólio Pontuado'!U60 -> 3.95 | Q16: ='Portfólio Pontuado'!T60 -> 4 | R16: F
P17: ='Portfólio Pontuado'!U61 -> 3.15 | Q17: ='Portfólio Pontuado'!T61 -> 3.75 | R17: F
P18: ='Portfólio Pontuado'!U62 -> 3.7 | Q18: ='Portfólio Pontuado'!T62 -> 4.25 | R18: F
P19: ='Portfólio Pontuado'!U65 -> 2.9 | Q19: ='Portfólio Pontuado'!T65 -> 3.65 | R19: F
P20: ='Portfólio Pontuado'!U69 -> 2.9 | Q20: ='Portfólio Pontuado'!T69 -> 3.85 | R20: F
P21: ='Portfólio Pontuado'!U72 -> 2.9 | Q21: ='Portfólio Pontuado'!T72 -> 3.7 | R21: F
P22: ='Portfólio Pontuado'!U73 -> 3.15 | Q22: ='Portfólio Pontuado'!T73 -> 3.75 | R22: F
P23: ='Portfólio Pontuado'!U80 -> 2.4 | Q23: ='Portfólio Pontuado'!T80 -> 3.25 | R23: F
P25: ='Portfólio Pontuado'!U26 -> 2.95 | Q25: ='Portfólio Pontuado'!T26 -> 3.05 | R25: I
P26: ='Portfólio Pontuado'!U47 -> 2.9 | Q26: ='Portfólio Pontuado'!T47 -> 2.65 | R26: I
P27: ='Portfólio Pontuado'!U50 -> 3.4 | Q27: ='Portfólio Pontuado'!T50 -> 2.95 | R27: I
P28: ='Portfólio Pontuado'!U71 -> 3.4 | Q28: ='Portfólio Pontuado'!T71 -> 3.5 | R28: I
P30: ='Portfólio Pontuado'!U14 -> 2.4 | Q30: ='Portfólio Pontuado'!T14 -> 2.95 | R30: C
P31: ='Portfólio Pontuado'!U35 -> 3.4 | Q31: ='Portfólio Pontuado'!T35 -> 3.55 | R31: C
P33: ='Portfólio Pontuado'!U5 -> 3.15 | Q33: ='Portfólio Pontuado'!T5 -> 3.85 | R33: O
P34: ='Portfólio Pontuado'!U7 -> 2.4 | Q34: ='Portfólio Pontuado'!T7 -> 2.3 | R34: O
P35: ='Portfólio Pontuado'!U8 -> 2.4 | Q35: ='Portfólio Pontuado'!T8 -> 2.3 | R35: O
P36: ='Portfólio Pontuado'!U9 -> 2.4 | Q36: ='Portfólio Pontuado'!T9 -> 3 | R36: O
P37: ='Portfólio Pontuado'!U11 -> 2.4 | Q37: ='Portfólio Pontuado'!T11 -> 3.3 | R37: O
P38: ='Portfólio Pontuado'!U12 -> 2.4 | Q38: ='Portfólio Pontuado'!T12 -> 2.65 | R38: O
P39: ='Portfólio Pontuado'!U13 -> 2.9 | Q39: ='Portfólio Pontuado'!T13 -> 3.7 | R39: O
P40: ='Portfólio Pontuado'!U15 -> 2.9 | Q40: ='Portfólio Pontuado'!T15 -> 3.6 | R40: O
P41: ='Portfólio Pontuado'!U16 -> 2.4 | Q41: ='Portfólio Pontuado'!T16 -> 3.05 | R41: O
P42: ='Portfólio Pontuado'!U17 -> 3.4 | Q42: ='Portfólio Pontuado'!T17 -> 4.05 | R42: O
P43: ='Portfólio Pontuado'!U18 -> 2.4 | Q43: ='Portfólio Pontuado'!T18 -> 2.3 | R43: O
P44: ='Portfólio Pontuado'!U19 -> 2.4 | Q44: ='Portfólio Pontuado'!T19 -> 2.3 | R44: O
P45: ='Portfólio Pontuado'!U21 -> 2.4 | Q45: ='Portfólio Pontuado'!T21 -> 3 | R45: O
...

Sheet Resumo
B2: Resumo do Portfólio
B4: Distribuição por quadrante | F4: Distribuição por perspectiva
B5: Quadrante | C5: Projetos | D5: % portfólio | F5: Perspectiva | G5: Projetos | H5: % portfólio
B6: Quick Win | C6: =COUNTIF('Portfólio Pontuado'!V5:V81,"Quick Win") -> 27 | D6: =COUNTIF('Portfólio Pontuado'!V5:V81,"Quick Win")/COUNTA('Portfólio Pontuado'!V5:V81) -> 0.35064935 | F6: Financeiro & Administrativo | G6: =SUMPRODUCT(--(LEFT('Portfólio Pontuado'!D5:D81,1)="F")) -> 17 | H6: =G6/COUNTA('Portfólio Pontuado'!V5:V81) -> 0.22077922
B7: Big Bet | C7: =COUNTIF('Portfólio Pontuado'!V5:V81,"Big Bet") -> 21 | D7: =COUNTIF('Portfólio Pontuado'!V5:V81,"Big Bet")/COUNTA('Portfólio Pontuado'!V5:V81) -> 0.27272727 | F7: Marca | G7: =SUMPRODUCT(--(LEFT('Portfólio Pontuado'!D5:D81,1)="M")) -> 0 | H7: =G7/COUNTA('Portfólio Pontuado'!V5:V81) -> 0
B8: Fill In | C8: =COUNTIF('Portfólio Pontuado'!V5:V81,"Fill In") -> 26 | D8: =COUNTIF('Portfólio Pontuado'!V5:V81,"Fill In")/COUNTA('Portfólio Pontuado'!V5:V81) -> 0.33766234 | F8: Inovação | G8: =SUMPRODUCT(--(LEFT('Portfólio Pontuado'!D5:D81,1)="I")) -> 4 | H8: =G8/COUNTA('Portfólio Pontuado'!V5:V81) -> 0.051948052
B9: Money Pit | C9: =COUNTIF('Portfólio Pontuado'!V5:V81,"Money Pit") -> 3 | D9: =COUNTIF('Portfólio Pontuado'!V5:V81,"Money Pit")/COUNTA('Portfólio Pontuado'!V5:V81) -> 0.038961039 | F9: Cliente | G9: =SUMPRODUCT(--(LEFT('Portfólio Pontuado'!D5:D81,1)="C")) -> 2 | H9: =G9/COUNTA('Portfólio Pontuado'!V5:V81) -> 0.025974026
F10: Capital Organizacional | G10: =SUMPRODUCT(--(LEFT('Portfólio Pontuado'!D5:D81,1)="O")) -> 51 | H10: =G10/COUNTA('Portfólio Pontuado'!V5:V81) -> 0.66233766
F11: Capital Humano | G11: =SUMPRODUCT(--(LEFT('Portfólio Pontuado'!D5:D81,1)="H")) -> 3 | H11: =G11/COUNTA('Portfólio Pontuado'!V5:V81) -> 0.038961039
B14: Métricas-chave
B15: Total de projetos | D15: =COUNTA('Portfólio Pontuado'!V5:V81) -> 77
B16: Impacto efetivo médio | D16: =AVERAGE('Portfólio Pontuado'!T5:T81) -> 3.2298701
B17: Esforço médio | D17: =AVERAGE('Portfólio Pontuado'!U5:U81) -> 2.8597403
B18: Projetos com confiança Baixa | D18: =COUNTIF('Portfólio Pontuado'!P5:P81,"Baixa") -> 0
B19: % com confiança Baixa | D19: =COUNTIF('Portfólio Pontuado'!P5:P81,"Baixa")/COUNTA('Portfólio Pontuado'!V5:V81) -> 0
B22: Observações desta primeira rodada
B23: • Toda confiança começa em Baixa porque os scores foram pré-classificados por heurística (título + diretoria). À medida que cada PO validar, eleve para Média/Alta — o impacto efetivo sobe automaticamente.
B24: • Modulador de criticidade está em 1.0 para todos os 19 pilares. Quando a diretoria definir focos do ciclo 2026, ajuste na aba Configuração — todos os scores recalculam.
B25: • Linhas divisórias dos quadrantes em 3.0. Calibre conforme o portfólio: se quase tudo cair em Quick Win, suba para 3.5. Se quase tudo cair em Money Pit, desça para 2.5.
B26: • Os pré-scores são chute educado — não é vergonha mudar 30-40% deles na primeira passagem. A planilha só vale o que o PMO investe revisando.
